{
    "textPayload": "Traceback (most recent call last):\n  File \"/layers/google.python.pip/pip/lib/python3.9/site-packages/gunicorn/arbiter.py\", line 589, in spawn_worker\n    worker.init_process()\n  File \"/layers/google.python.pip/pip/lib/python3.9/site-packages/uvicorn/workers.py\", line 66, in init_process\n    super(UvicornWorker, self).init_process()\n  File \"/layers/google.python.pip/pip/lib/python3.9/site-packages/gunicorn/workers/base.py\", line 134, in init_process\n    self.load_wsgi()\n  File \"/layers/google.python.pip/pip/lib/python3.9/site-packages/gunicorn/workers/base.py\", line 146, in load_wsgi\n    self.wsgi = self.app.wsgi()\n  File \"/layers/google.python.pip/pip/lib/python3.9/site-packages/gunicorn/app/base.py\", line 67, in wsgi\n    self.callable = self.load()\n  File \"/layers/google.python.pip/pip/lib/python3.9/site-packages/gunicorn/app/wsgiapp.py\", line 58, in load\n    return self.load_wsgiapp()\n  File \"/layers/google.python.pip/pip/lib/python3.9/site-packages/gunicorn/app/wsgiapp.py\", line 48, in load_wsgiapp\n    return util.import_app(self.app_uri)\n  File \"/layers/google.python.pip/pip/lib/python3.9/site-packages/gunicorn/util.py\", line 359, in import_app\n    mod = importlib.import_module(module)\n  File \"/layers/google.python.runtime/python/lib/python3.9/importlib/__init__.py\", line 127, in import_module\n    return _bootstrap._gcd_import(name[level:], package, level)\n  File \"<frozen importlib._bootstrap>\", line 1030, in _gcd_import\n  File \"<frozen importlib._bootstrap>\", line 1007, in _find_and_load\n  File \"<frozen importlib._bootstrap>\", line 986, in _find_and_load_unlocked\n  File \"<frozen importlib._bootstrap>\", line 680, in _load_unlocked\n  File \"<frozen importlib._bootstrap_external>\", line 850, in exec_module\n  File \"<frozen importlib._bootstrap>\", line 228, in _call_with_frames_removed\n  File \"/workspace/app/main.py\", line 3, in <module>\n    from .routers import (\n  File \"/workspace/app/routers/upload_file.py\", line 16, in <module>\n    client = storage.Client()\n  File \"/layers/google.python.pip/pip/lib/python3.9/site-packages/google/cloud/storage/client.py\", line 167, in __init__\n    super(Client, self).__init__(\n  File \"/layers/google.python.pip/pip/lib/python3.9/site-packages/google/cloud/client/__init__.py\", line 321, in __init__\n    Client.__init__(\n  File \"/layers/google.python.pip/pip/lib/python3.9/site-packages/google/cloud/client/__init__.py\", line 178, in __init__\n    credentials, _ = google.auth.default(scopes=scopes)\n  File \"/layers/google.python.pip/pip/lib/python3.9/site-packages/google/auth/_default.py\", line 659, in default\n    credentials, project_id = checker()\n  File \"/layers/google.python.pip/pip/lib/python3.9/site-packages/google/auth/_default.py\", line 652, in <lambda>\n    lambda: _get_explicit_environ_credentials(quota_project_id=quota_project_id),\n  File \"/layers/google.python.pip/pip/lib/python3.9/site-packages/google/auth/_default.py\", line 272, in _get_explicit_environ_credentials\n    credentials, project_id = load_credentials_from_file(\n  File \"/layers/google.python.pip/pip/lib/python3.9/site-packages/google/auth/_default.py\", line 116, in load_credentials_from_file\n    raise exceptions.DefaultCredentialsError(\ngoogle.auth.exceptions.DefaultCredentialsError: File /home/mmk/Downloads/mobile-doc-backend-analytics-sa.json was not found.",
    "insertId": "64fdd9a50007ed0fdb5eb25e",
    "resource": {
      "type": "gae_app",
      "labels": {
        "module_id": "default",
        "version_id": "staging",
        "zone": "asia-south1-4",
        "project_id": "mobile-doc-backend"
      }
    },
    "timestamp": "2023-09-10T14:58:45.519439Z",
    "severity": "ERROR",
    "labels": {
      "clone_id": "00c61b117c6780f3ae50f585f022fcca7dedd0d11eefeae5cb9dccc0ef29540db0212f22032406b15c1b629c9767e053e846a72a3722fa8840df"
    },
    "logName": "projects/mobile-doc-backend/logs/stderr",
    "receiveTimestamp": "2023-09-10T14:58:45.832622629Z"
  }